Workbook

Sheet Dashboard
A1: Sales & Revenue Analysis Dashboard
A2: Interactive KPI overview, revenue trends, and top-performing products (FY2024)
A4: Region Filter: | B4: All | D4: (Change the dropdown to filter Total Revenue, Units, Orders & AOV below)
A6: Total Revenue | E6: Total Units Sold | I6: Total Orders | M6: Avg Order Value
A7: =IF($B$4="All",SUM('Raw Data'!$I$2:$I$421),SUMIFS('Raw Data'!$I$2:$I$421,'Raw Data'!$C$2:$C$421,$B$4)) -> 174720.08 | E7: =IF($B$4="All",SUM('Raw Data'!$G$2:$G$421),SUMIFS('Raw Data'!$G$2:$G$421,'Raw Data'!$C$2:$C$421,$B$4)) -> 2992 | I7: =IF($B$4="All",COUNTA('Raw Data'!$A$2:$A$421),COUNTIFS('Raw Data'!$C$2:$C$421,$B$4)) -> 420 | M7: =IF(I7=0,0,A7/I7) -> 416.00019
A10: Top-Performing Product: | C10: =INDEX(Summary!$A$18:$A$29,MATCH(MAX(Summary!$B$18:$B$29),Summary!$B$18:$B$29,0)) -> Smart Watch | H10: Its Revenue: | I10: =MAX(Summary!$B$18:$B$29) -> 30677.64

Sheet Raw Data
A1: Order ID | B1: Date | C1: Region | D1: Category | E1: Product | F1: Sales Rep | G1: Units Sold | H1: Unit Price | I1: Revenue
A2: 1001 | B2: 45292 | C2: East | D2: Sports | E2: Yoga Mat | F2: B. Patel | G2: 10 | H2: 24.99 | I2: =G2*H2 -> 249.9
A3: 1002 | B3: 45293 | C3: South | D3: Apparel | E3: Cotton T-Shirt | F3: F. Meyer | G3: 5 | H3: 19.99 | I3: =G3*H3 -> 99.95
A4: 1003 | B4: 45293 | C4: East | D4: Books | E4: Bestseller Novel | F4: E. Rossi | G4: 3 | H4: 14.99 | I4: =G4*H4 -> 44.97
A5: 1004 | B5: 45295 | C5: North | D5: Electronics | E5: Bluetooth Speaker | F5: B. Patel | G5: 2 | H5: 39.99 | I5: =G5*H5 -> 79.98
A6: 1005 | B6: 45295 | C6: West | D6: Home & Kitchen | E6: Coffee Maker | F6: B. Patel | G6: 3 | H6: 54.99 | I6: =G6*H6 -> 164.97
A7: 1006 | B7: 45299 | C7: South | D7: Electronics | E7: Bluetooth Speaker | F7: B. Patel | G7: 7 | H7: 39.99 | I7: =G7*H7 -> 279.93
A8: 1007 | B8: 45299 | C8: South | D8: Books | E8: Bestseller Novel | F8: C. Nguyen | G8: 1 | H8: 14.99 | I8: =G8*H8 -> 14.99
A9: 1008 | B9: 45300 | C9: North | D9: Apparel | E9: Cotton T-Shirt | F9: C. Nguyen | G9: 4 | H9: 19.99 | I9: =G9*H9 -> 79.96
A10: 1009 | B10: 45301 | C10: South | D10: Apparel | E10: Denim Jacket | F10: B. Patel | G10: 9 | H10: 59.99 | I10: =G10*H10 -> 539.91
A11: 1010 | B11: 45302 | C11: West | D11: Sports | E11: Yoga Mat | F11: D. Cohen | G11: 1 | H11: 24.99 | I11: =G11*H11 -> 24.99
A12: 1011 | B12: 45303 | C12: West | D12: Sports | E12: Dumbbell Set | F12: C. Nguyen | G12: 1 | H12: 69.99 | I12: =G12*H12 -> 69.99
A13: 1012 | B13: 45305 | C13: South | D13: Electronics | E13: Bluetooth Speaker | F13: F. Meyer | G13: 10 | H13: 39.99 | I13: =G13*H13 -> 399.9
... A421: 1420 | B421: 45656 | C421: South | D421: Books | E421: Bestseller Novel | F421: C. Nguyen | G421: 10 | H421: 14.99 | I421: =G421*H421 -> 149.9

Sheet Summary
A1: Monthly Revenue Trend
A2: Month | B2: Revenue
A3: Jan | B3: =SUMPRODUCT((TEXT('Raw Data'!$B$2:$B$421,"mmm")=A3)*'Raw Data'!$I$2:$I$421) -> 7453.41
A4: Feb | B4: =SUMPRODUCT((TEXT('Raw Data'!$B$2:$B$421,"mmm")=A4)*'Raw Data'!$I$2:$I$421) -> 18247.16
A5: Mar | B5: =SUMPRODUCT((TEXT('Raw Data'!$B$2:$B$421,"mmm")=A5)*'Raw Data'!$I$2:$I$421) -> 12432.72
A6: Apr | B6: =SUMPRODUCT((TEXT('Raw Data'!$B$2:$B$421,"mmm")=A6)*'Raw Data'!$I$2:$I$421) -> 11158.23
A7: May | B7: =SUMPRODUCT((TEXT('Raw Data'!$B$2:$B$421,"mmm")=A7)*'Raw Data'!$I$2:$I$421) -> 15927.08
A8: Jun | B8: =SUMPRODUCT((TEXT('Raw Data'!$B$2:$B$421,"mmm")=A8)*'Raw Data'!$I$2:$I$421) -> 18037.35
A9: Jul | B9: =SUMPRODUCT((TEXT('Raw Data'!$B$2:$B$421,"mmm")=A9)*'Raw Data'!$I$2:$I$421) -> 9247.92
A10: Aug | B10: =SUMPRODUCT((TEXT('Raw Data'!$B$2:$B$421,"mmm")=A10)*'Raw Data'!$I$2:$I$421) -> 15052.62
A11: Sep | B11: =SUMPRODUCT((TEXT('Raw Data'!$B$2:$B$421,"mmm")=A11)*'Raw Data'!$I$2:$I$421) -> 9563.19
A12: Oct | B12: =SUMPRODUCT((TEXT('Raw Data'!$B$2:$B$421,"mmm")=A12)*'Raw Data'!$I$2:$I$421) -> 13342.78
A13: Nov | B13: =SUMPRODUCT((TEXT('Raw Data'!$B$2:$B$421,"mmm")=A13)*'Raw Data'!$I$2:$I$421) -> 17456.91
A14: Dec | B14: =SUMPRODUCT((TEXT('Raw Data'!$B$2:$B$421,"mmm")=A14)*'Raw Data'!$I$2:$I$421) -> 26800.71
A16: Product Performance
A17: Product | B17: Revenue | C17: Units Sold
A18: Air Fryer | B18: =SUMIFS('Raw Data'!$I$2:$I$421,'Raw Data'!$E$2:$E$421,A18) -> 29336.74 | C18: =SUMIFS('Raw Data'!$G$2:$G$421,'Raw Data'!$E$2:$E$421,A18) -> 326
A19: Bestseller Novel | B19: =SUMIFS('Raw Data'!$I$2:$I$421,'Raw Data'!$E$2:$E$421,A19) -> 2968.02 | C19: =SUMIFS('Raw Data'!$G$2:$G$421,'Raw Data'!$E$2:$E$421,A19) -> 198
A20: Blender | B20: =SUMIFS('Raw Data'!$I$2:$I$421,'Raw Data'!$E$2:$E$421,A20) -> 12867.14 | C20: =SUMIFS('Raw Data'!$G$2:$G$421,'Raw Data'!$E$2:$E$421,A20) -> 286
A21: Bluetooth Speaker | B21: =SUMIFS('Raw Data'!$I$2:$I$421,'Raw Data'!$E$2:$E$421,A21) -> 12076.98 | C21: =SUMIFS('Raw Data'!$G$2:$G$421,'Raw Data'!$E$2:$E$421,A21) -> 302
A22: Coffee Maker | B22: =SUMIFS('Raw Data'!$I$2:$I$421,'Raw Data'!$E$2:$E$421,A22) -> 14077.44 | C22: =SUMIFS('Raw Data'!$G$2:$G$421,'Raw Data'!$E$2:$E$421,A22) -> 256
A23: Cotton T-Shirt | B23: =SUMIFS('Raw Data'!$I$2:$I$421,'Raw Data'!$E$2:$E$421,A23) -> 3378.31 | C23: =SUMIFS('Raw Data'!$G$2:$G$421,'Raw Data'!$E$2:$E$421,A23) -> 169
A24: Denim Jacket | B24: =SUMIFS('Raw Data'!$I$2:$I$421,'Raw Data'!$E$2:$E$421,A24) -> 13497.75 | C24: =SUMIFS('Raw Data'!$G$2:$G$421,'Raw Data'!$E$2:$E$421,A24) -> 225
A25: Dumbbell Set | B25: =SUMIFS('Raw Data'!$I$2:$I$421,'Raw Data'!$E$2:$E$421,A25) -> 23446.65 | C25: =SUMIFS('Raw Data'!$G$2:$G$421,'Raw Data'!$E$2:$E$421,A25) -> 335
A26: Running Shoes | B26: =SUMIFS('Raw Data'!$I$2:$I$421,'Raw Data'!$E$2:$E$421,A26) -> 15522.93 | C26: =SUMIFS('Raw Data'!$G$2:$G$421,'Raw Data'!$E$2:$E$421,A26) -> 207
A27: Smart Watch | B27: =SUMIFS('Raw Data'!$I$2:$I$421,'Raw Data'!$E$2:$E$421,A27) -> 30677.64 | C27: =SUMIFS('Raw Data'!$G$2:$G$421,'Raw Data'!$E$2:$E$421,A27) -> 236
A28: Wireless Earbuds | B28: =SUMIFS('Raw Data'!$I$2:$I$421,'Raw Data'!$E$2:$E$421,A28) -> 11147.77 | C28: =SUMIFS('Raw Data'!$G$2:$G$421,'Raw Data'!$E$2:$E$421,A28) -> 223
A29: Yoga Mat | B29: =SUMIFS('Raw Data'!$I$2:$I$421,'Raw Data'!$E$2:$E$421,A29) -> 5722.71 | C29: =SUMIFS('Raw Data'!$G$2:$G$421,'Raw Data'!$E$2:$E$421,A29) -> 229
A31: Region Performance
A32: Region | B32: Revenue
A33: East | B33: =SUMIFS('Raw Data'!$I$2:$I$421,'Raw Data'!$C$2:$C$421,A33) -> 41132.85
A34: North | B34: =SUMIFS('Raw Data'!$I$2:$I$421,'Raw Data'!$C$2:$C$421,A34) -> 43788.08
A35: South | B35: =SUMIFS('Raw Data'!$I$2:$I$421,'Raw Data'!$C$2:$C$421,A35) -> 43297.53
A36: West | B36: =SUMIFS('Raw Data'!$I$2:$I$421,'Raw Data'!$C$2:$C$421,A36) -> 46501.62
A38: Category Performance
A39: Category | B39: Revenue
A40: Apparel | B40: =SUMIFS('Raw Data'!$I$2:$I$421,'Raw Data'!$D$2:$D$421,A40) -> 32398.99
A41: Books | B41: =SUMIFS('Raw Data'!$I$2:$I$421,'Raw Data'!$D$2:$D$421,A41) -> 2968.02
A42: Electronics | B42: =SUMIFS('Raw Data'!$I$2:$I$421,'Raw Data'!$D$2:$D$421,A42) -> 53902.39
A43: Home & Kitchen | B43: =SUMIFS('Raw Data'!$I$2:$I$421,'Raw Data'!$D$2:$D$421,A43) -> 56281.32
...
